Workbook

Sheet 1. Exec Dashboard
A1: FIRE FIGHTING SYSTEM — NEW DC
A2: Installation Schedule & Project Responsibility Tracker
A3: Survey Date: 30-Jun-2026 | PM: Kharsan Mujeb Al Ajmi | [OFFICIAL LOGO — TO BE INSERTED]
A5: PROPOSED PLANNING BASELINE — Proposed planning dates are preliminary and subject to confirmation by the Project Owner, PM, Contractor and relevant stakeholders. Only items marked CONFIRMED (SURVEY) are supported by the source report.
A7: EXECUTIVE SUMMARY
B8: Project | F8: Fire Fighting System for New DC
B9: Location / Asset | F9: Mobile / Trailer-based DC
B10: Survey Date | F10: 30-Jun-2026
B11: Project Manager | F11: Kharsan Mujeb Al Ajmi
B12: Source Document | F12: RC Vehicle Survey Report – Fire Fighting System for New DC
B13: Recommended Systems | F13: Fire Alarm System · Fire Suppression System
B15: Current Situation | F15: Per the RC Vehicle Survey Report dated 30-Jun-2026: installation of Racks and Cabinets has not yet started in the available trailers, and the power source in Trailer-2 is currently unavailable because partition works are still ongoing. The survey recommends providing a Fire Alarm System and a Fire Suppression System. No installation start, duration or completion dates are stated in the source document.
B16: Overall Status | F16: PLANNING / SITE READINESS PENDING
A18: KEY PERFORMANCE INDICATORS — calculated live from the Master Schedule
B20: TOTAL ACTIVITIES | E20: COMPLETED | H20: IN PROGRESS | K20: BLOCKED | N20: NOT STARTED | Q20: OVERALL COMPLETE
B21: =COUNTA('2. Master Schedule'!$B$10:$B$63) -> 49 | E21: =COUNTIF('2. Master Schedule'!$J$10:$J$63,"Completed") -> 1 | H21: =COUNTIF('2. Master Schedule'!$J$10:$J$63,"In Progress") -> 1 | K21: =COUNTIF('2. Master Schedule'!$J$10:$J$63,"Blocked") -> 2 | N21: =COUNTIF('2. Master Schedule'!$J$10:$J$63,"Not Started") -> 41 | Q21: =IFERROR(AVERAGE('2. Master Schedule'!$K$10:$K$63),0) -> 0.020408163
B22: Across 6 phases | E22: Confirmed by survey | H22: Partition works ongoing | K22: Trailer-2 power | N22: Awaiting site readiness | Q22: Weighted equally
A24: CRITICAL CONSTRAINTS — confirmed by the survey
B26: CONSTRAINT 01 · RACKS & CABINETS | K26: CONSTRAINT 02 · TRAILER-2 POWER
B27: Installation of Racks and Cabinets has not yet started in the available trailers. | K27: The power source in Trailer-2 is currently unavailable because partition works are still ongoing.
B28: Impact: gates fire alarm and suppression activities that interface with racks and cabinets (4.01, 4.04, 4.07) and therefore the whole installation phase. Required action: confirm scope, contractor and start date (Action A03). Responsible: Main Contractor (TBC) Target resolution: TBD | K28: Impact: blocks power availability verification (2.02) and power and control connections (4.08); gates functional testing (5.05) and Trailer-2 handover. Required action: complete partition works, then verify and energise (Actions A01, A02). Responsible: Civil / Partition Contractor (TBC) → Electrical Contractor (TBC) Target resolution: TBD
A30: KEY MILESTONES
B32: Milestone | F32: Target Date | H32: Owner | J32: Status | L32: Dependency | O32: Remarks
B33: Project Kickoff | F33: TBD | H33: TBC | J33: Not Started | L33: Stakeholder confirmation | O33: Baseline agreement and governance sign-off.
B34: Site Readiness Confirmed | F34: TBD | H34: TBC | J34: Not Started | L34: Partition works + installation area verification | O34: Gate for all site activities.
B35: Power Available (Trailer-2) | F35: TBD | H35: TBC | J35: Blocked | L35: Completion of partition works | O35: CONFIRMED constraint: Trailer-2 power source currently unavailable.
B36: Racks & Cabinets Ready | F36: TBD | H36: TBC | J36: Not Started | L36: Installation of Racks and Cabinets (2.04) | O36: CONFIRMED constraint: installation has not yet started.
B37: Engineering Approved | F37: TBD | H37: TBC | J37: Pending Approval | L37: Shop drawing and material approval (3.05) | O37: Approving authority to be confirmed.
B38: Materials Available on Site | F38: TBD | H38: TBC | J38: Pending Material | L38: Procurement and delivery (3.06 / 3.07) | O38: Lead times unknown until equipment selection is confirmed.
B39: Installation Start | F39: TBD | H39: TBC | J39: Not Started | L39: M02 + M04 + M06 | O39: Cannot start before all three readiness gates close.
B40: Installation Complete | F40: TBD | H40: TBC | J40: Not Started | L40: System integration (4.09) | O40: Includes power and control connections.
B41: Testing Complete | F41: TBD | H41: TBC | J41: Not Started | L41: Integration testing (5.06) | O41: Both recommended systems tested.
B42: Defects Closed | F42: TBD | H42: TBC | J42: Not Started | L42: Rectification and retesting (5.08 / 5.09) | O42: Zero open critical defects.
B43: Final Acceptance | F43: TBD | H43: TBC | J43: Not Started | L43: Final acceptance and sign-off (6.07) | O43: Acceptance criteria to be agreed at kickoff.
... B45: Project Closeout | F45: TBD | H45: TBC | J45: Not Started | L45: Project closeout (6.09) | O45: Overall project completion date TBD.
A47: MANAGEMENT ATTENTION — critical path actions
B49: Action ID | D49: Required Action | J49: Responsible | M49: Priority | O49: Status | Q49: Escalation / Remarks
B50: A01 | D50: Complete partition works in Trailer-2 | J50: Civil / Partition Contractor (TBC) | M50: Critical | O50: In Progress | Q50: CRITICAL PATH — first link in the Trailer-2 readiness chain.
B51: A02 | D51: Confirm power availability in Trailer-2 once partitions are complete | J51: Electrical Contractor (TBC) | M51: Critical | O51: Blocked | Q51: CRITICAL PATH — gates power and control connections and functional testing.
B52: A03 | D52: Start and complete installation of Racks and Cabinets | J52: Main Contractor (TBC) | M52: Critical | O52: Not Started | Q52: CRITICAL PATH — gates all rack/cabinet-interfacing fire system works.
...

Sheet 2. Master Schedule
A1: FIRE FIGHTING SYSTEM — NEW DC
A2: Installation Schedule & Project Responsibility Tracker
A3: Survey Date: 30-Jun-2026 | PM: Kharsan Mujeb Al Ajmi | [OFFICIAL LOGO — TO BE INSERTED]
A5: PROPOSED PLANNING BASELINE — Proposed planning dates are preliminary and subject to confirmation by the Project Owner, PM, Contractor and relevant stakeholders. Only items marked CONFIRMED (SURVEY) are supported by the source report.
A6: HOW TO USE · Shaded input cells (Planned Start / Planned Finish / % Complete) and blue text are for the project team to complete. · Duration, Days Remaining and Schedule Flag calculate automatically. · Status is a drop-down list. · Remarks tagged “CONFIRMED (SURVEY)” are supported by the source report; everything else is a proposed planning value or TBC.
A8: ID | B8: WBS | C8: Phase | D8: Activity | E8: Trailer / Location | F8: Prede- cessor | G8: Planned Start (enter date) | H8: Planned Finish (enter date) | I8: Duration (days) | J8: Status | K8: % Complete | L8: Responsible Person | M8: Role | N8: Project Owner | O8: Contractor | P8: Dependency | Q8: Risk / Blocker | R8: Approval Required | S8: Remarks | T8: Days Remaining (auto) | U8: Schedule Flag (auto)
A9: Phase 1 — Project Preparation · Proposed baseline: Week 1 – Week 2
A10: 1 | B10: 1.01 | C10: Phase 1 — Project Preparation | D10: Project kickoff meeting and baseline agreement | E10: All trailers | F10: — | I10: =IF(OR($G10="",$H10=""),"TBD",$H10-$G10+1) -> TBD | J10: Not Started | K10: 0 | L10: Kharsan Mujeb Al Ajmi | M10: Project Manager | N10: TBC | O10: TBC | P10: Stakeholder availability | Q10: — | R10: No | S10: Kickoff to confirm scope, team, baseline dates and reporting cycle. | T10: =IF($H10="","TBD",IF($J10="Completed","Closed",$H10-TODAY())) -> TBD | U10: =IF($J10="Completed","COMPLETE",IF(AND($H10<>"",$H10<TODAY()),"OVERDUE",IF($J10="Blocked","BLOCKED",IF(ISNUMBER(SEARCH("Power availability",$P10)),"PENDING POWER AVAILABILITY",IF(IFERROR(IF($F10="—",FALSE(),INDEX($J:$J,MATCH($F10,$B:$B,0))<>"Completed"),FALSE()),"PENDING PREDECESSOR",IF($J10="At Risk","AT RISK",IF(OR($J10="Pending Approval",$J10="Pending Material"),UPPER($J10),IF($J10="In Progress","IN PROGRESS",IF($J10="Ready to Start","READY TO START","ON PLAN"))))))))) -> ON PLAN
A11: 2 | B11: 1.02 | C11: Phase 1 — Project Preparation | D11: Site survey execution — RC Vehicle Survey | E11: Mobile / Trailer-based DC | F11: — | G11: 46203 | H11: 46203 | I11: =IF(OR($G11="",$H11=""),"TBD",$H11-$G11+1) -> 1 | J11: Completed | K11: 1 | L11: TBC | M11: Survey Team | N11: TBC | O11: TBC | P11: — | Q11: — | R11: No | S11: CONFIRMED (SURVEY): Survey carried out and reported on 30-Jun-2026. Completed prior to this baseline. | T11: =IF($H11="","TBD",IF($J11="Completed","Closed",$H11-TODAY())) -> Closed | U11: =IF($J11="Completed","COMPLETE",IF(AND($H11<>"",$H11<TODAY()),"OVERDUE",IF($J11="Blocked","BLOCKED",IF(ISNUMBER(SEARCH("Power availability",$P11)),"PENDING POWER AVAILABILITY",IF(IFERROR(IF($F11="—",FALSE(),INDEX($J:$J,MATCH($F11,$B:$B,0))<>"Completed"),FALSE()),"PENDING PREDECESSOR",IF($J11="At Risk","AT RISK",IF(OR($J11="Pending Approval",$J11="Pending Material"),UPPER($J11),IF($J11="In Progress","IN PROGRESS",IF($J11="Ready to Start","READY TO START","ON PLAN"))))))))) -> COMPLETE
A12: 3 | B12: 1.03 | C12: Phase 1 — Project Preparation | D12: Review of RC Vehicle Survey Report dated 30-Jun-2026 | E12: All trailers | F12: 1.02 | I12: =IF(OR($G12="",$H12=""),"TBD",$H12-$G12+1) -> TBD | J12: Ready to Start | K12: 0 | L12: Kharsan Mujeb Al Ajmi | M12: Project Manager | N12: TBC | O12: TBC | P12: Survey report issued (1.02 complete) | Q12: — | R12: No | S12: Source document is available; formal team review not yet recorded. | T12: =IF($H12="","TBD",IF($J12="Completed","Closed",$H12-TODAY())) -> TBD | U12: =IF($J12="Completed","COMPLETE",IF(AND($H12<>"",$H12<TODAY()),"OVERDUE",IF($J12="Blocked","BLOCKED",IF(ISNUMBER(SEARCH("Power availability",$P12)),"PENDING POWER AVAILABILITY",IF(IFERROR(IF($F12="—",FALSE(),INDEX($J:$J,MATCH($F12,$B:$B,0))<>"Completed"),FALSE()),"PENDING PREDECESSOR",IF($J12="At Risk","AT RISK",IF(OR($J12="Pending Approval",$J12="Pending Material"),UPPER($J12),IF($J12="In Progress","IN PROGRESS",IF($J12="Ready to Start","READY TO START","ON PLAN"))))))))) -> READY TO START
A13: 4 | B13: 1.04 | C13: Phase 1 — Project Preparation | D13: Scope confirmation — Fire Alarm System and Fire Suppression System | E13: All trailers | F13: 1.03 | I13: =IF(OR($G13="",$H13=""),"TBD",$H13-$G13+1) -> TBD | J13: Not Started | K13: 0 | L13: Kharsan Mujeb Al Ajmi | M13: Project Manager | N13: TBC | O13: TBC | P13: Survey report review complete | Q13: — | R13: Yes | S13: CONFIRMED (SURVEY): Survey recommends providing a Fire Alarm System and a Fire Suppression System. | T13: =IF($H13="","TBD",IF($J13="Completed","Closed",$H13-TODAY())) -> TBD | U13: =IF($J13="Completed","COMPLETE",IF(AND($H13<>"",$H13<TODAY()),"OVERDUE",IF($J13="Blocked","BLOCKED",IF(ISNUMBER(SEARCH("Power availability",$P13)),"PENDING POWER AVAILABILITY",IF(IFERROR(IF($F13="—",FALSE(),INDEX($J:$J,MATCH($F13,$B:$B,0))<>"Completed"),FALSE()),"PENDING PREDECESSOR",IF($J13="At Risk","AT RISK",IF(OR($J13="Pending Approval",$J13="Pending Material"),UPPER($J13),IF($J13="In Progress","IN PROGRESS",IF($J13="Ready to Start","READY TO START","ON PLAN"))))))))) -> PENDING PREDECESSOR
A14: 5 | B14: 1.05 | C14: Phase 1 — Project Preparation | D14: Confirmation of project stakeholders, owner and governance | E14: N/A | F14: 1.01 | I14: =IF(OR($G14="",$H14=""),"TBD",$H14-$G14+1) -> TBD | J14: Not Started | K14: 0 | L14: Kharsan Mujeb Al Ajmi | M14: Project Manager | N14: TBC | O14: TBC | P14: Project Owner nomination | Q14: Project Owner not yet identified | R14: Yes | S14: Project Owner, Main Contractor, Fire System Contractor and Client Rep to be named. | T14: =IF($H14="","TBD",IF($J14="Completed","Closed",$H14-TODAY())) -> TBD | U14: =IF($J14="Completed","COMPLETE",IF(AND($H14<>"",$H14<TODAY()),"OVERDUE",IF($J14="Blocked","BLOCKED",IF(ISNUMBER(SEARCH("Power availability",$P14)),"PENDING POWER AVAILABILITY",IF(IFERROR(IF($F14="—",FALSE(),INDEX($J:$J,MATCH($F14,$B:$B,0))<>"Completed"),FALSE()),"PENDING PREDECESSOR",IF($J14="At Risk","AT RISK",IF(OR($J14="Pending Approval",$J14="Pending Material"),UPPER($J14),IF($J14="In Progress","IN PROGRESS",IF($J14="Ready to Start","READY TO START","ON PLAN"))))))))) -> PENDING PREDECESSOR
A15: 6 | B15: 1.06 | C15: Phase 1 — Project Preparation | D15: Site readiness verification walkdown | E15: All trailers | F15: 1.04 | I15: =IF(OR($G15="",$H15=""),"TBD",$H15-$G15+1) -> TBD | J15: Not Started | K15: 0 | L15: TBC | M15: Site Supervisor | N15: TBC | O15: TBC | P15: Scope confirmed | Q15: Site not yet ready — see Phase 2 | R15: No | S15: Joint walkdown to baseline actual readiness against survey findings. | T15: =IF($H15="","TBD",IF($J15="Completed","Closed",$H15-TODAY())) -> TBD | U15: =IF($J15="Completed","COMPLETE",IF(AND($H15<>"",$H15<TODAY()),"OVERDUE",IF($J15="Blocked","BLOCKED",IF(ISNUMBER(SEARCH("Power availability",$P15)),"PENDING POWER AVAILABILITY",IF(IFERROR(IF($F15="—",FALSE(),INDEX($J:$J,MATCH($F15,$B:$B,0))<>"Completed"),FALSE()),"PENDING PREDECESSOR",IF($J15="At Risk","AT RISK",IF(OR($J15="Pending Approval",$J15="Pending Material"),UPPER($J15),IF($J15="In Progress","IN PROGRESS",IF($J15="Ready to Start","READY TO START","ON PLAN"))))))))) -> PENDING PREDECESSOR
A16: 7 | B16: 1.07 | C16: Phase 1 — Project Preparation | D16: Confirmation of trailer availability | E16: All trailers | F16: 1.06 | I16: =IF(OR($G16="",$H16=""),"TBD",$H16-$G16+1) -> TBD | J16: Not Started | K16: 0 | L16: Kharsan Mujeb Al Ajmi | M16: Project Manager | N16: TBC | O16: TBC | P16: Walkdown complete | Q16: — | R16: No | S16: Number and identity of trailers released for installation to be confirmed. | T16: =IF($H16="","TBD",IF($J16="Completed","Closed",$H16-TODAY())) -> TBD | U16: =IF($J16="Completed","COMPLETE",IF(AND($H16<>"",$H16<TODAY()),"OVERDUE",IF($J16="Blocked","BLOCKED",IF(ISNUMBER(SEARCH("Power availability",$P16)),"PENDING POWER AVAILABILITY",IF(IFERROR(IF($F16="—",FALSE(),INDEX($J:$J,MATCH($F16,$B:$B,0))<>"Completed"),FALSE()),"PENDING PREDECESSOR",IF($J16="At Risk","AT RISK",IF(OR($J16="Pending Approval",$J16="Pending Material"),UPPER($J16),IF($J16="In Progress","IN PROGRESS",IF($J16="Ready to Start","READY TO START","ON PLAN"))))))))) -> PENDING PREDECESSOR
A17: 8 | B17: 1.08 | C17: Phase 1 — Project Preparation | D17: Confirmation of installation areas within trailers | E17: All trailers | F17: 1.07 | I17: =IF(OR($G17="",$H17=""),"TBD",$H17-$G17+1) -> TBD | J17: Not Started | K17: 0 | L17: TBC | M17: Fire & Life Safety Engineer | N17: TBC | O17: TBC | P17: Trailer availability confirmed | Q17: — | R17: No | S17: Installation areas to be agreed once partitions and rack layout are fixed. | T17: =IF($H17="","TBD",IF($J17="Completed","Closed",$H17-TODAY())) -> TBD | U17: =IF($J17="Completed","COMPLETE",IF(AND($H17<>"",$H17<TODAY()),"OVERDUE",IF($J17="Blocked","BLOCKED",IF(ISNUMBER(SEARCH("Power availability",$P17)),"PENDING POWER AVAILABILITY",IF(IFERROR(IF($F17="—",FALSE(),INDEX($J:$J,MATCH($F17,$B:$B,0))<>"Completed"),FALSE()),"PENDING PREDECESSOR",IF($J17="At Risk","AT RISK",IF(OR($J17="Pending Approval",$J17="Pending Material"),UPPER($J17),IF($J17="In Progress","IN PROGRESS",IF($J17="Ready to Start","READY TO START","ON PLAN"))))))))) -> PENDING PREDECESSOR
A18: Phase 2 — Civil / Site Readiness · Proposed baseline: Week 1 – Week 6
A19: 9 | B19: 2.01 | C19: Phase 2 — Civil / Site Readiness | D19: Completion of partition works | E19: Trailer-2 | F19: — | I19: =IF(OR($G19="",$H19=""),"TBD",$H19-$G19+1) -> TBD | J19: In Progress | K19: 0 | L19: TBC | M19: Civil / Partition Contractor | N19: TBC | O19: TBC | P19: Civil works front | Q19: Ongoing partition works block power availability | R19: No | S19: CONFIRMED (SURVEY): Partition works are still ongoing in Trailer-2. Completion date and % progress TBC. | T19: =IF($H19="","TBD",IF($J19="Completed","Closed",$H19-TODAY())) -> TBD | U19: =IF($J19="Completed","COMPLETE",IF(AND($H19<>"",$H19<TODAY()),"OVERDUE",IF($J19="Blocked","BLOCKED",IF(ISNUMBER(SEARCH("Power availability",$P19)),"PENDING POWER AVAILABILITY",IF(IFERROR(IF($F19="—",FALSE(),INDEX($J:$J,MATCH($F19,$B:$B,0))<>"Completed"),FALSE()),"PENDING PREDECESSOR",IF($J19="At Risk","AT RISK",IF(OR($J19="Pending Approval",$J19="Pending Material"),UPPER($J19),IF($J19="In Progress","IN PROGRESS",IF($J19="Ready to Start","READY TO START","ON PLAN"))))))))) -> IN PROGRESS
A20: 10 | B20: 2.02 | C20: Phase 2 — Civil / Site Readiness | D20: Power source availability verification and energisation | E20: Trailer-2 | F20: 2.01 | I20: =IF(OR($G20="",$H20=""),"TBD",$H20-$G20+1) -> TBD | J20: Blocked | K20: 0 | L20: TBC | M20: Electrical Contractor | N20: TBC | O20: TBC | P20: Completion of partition works + Power availability confirmation | Q20: Trailer-2 power source currently unavailable | R20: Yes | S20: CONFIRMED (SURVEY): Power source in Trailer-2 is currently unavailable because partition works are ongoing. | T20: =IF($H20="","TBD",IF($J20="Completed","Closed",$H20-TODAY())) -> TBD | U20: =IF($J20="Completed","COMPLETE",IF(AND($H20<>"",$H20<TODAY()),"OVERDUE",IF($J20="Blocked","BLOCKED",IF(ISNUMBER(SEARCH("Power availability",$P20)),"PENDING POWER AVAILABILITY",IF(IFERROR(IF($F20="—",FALSE(),INDEX($J:$J,MATCH($F20,$B:$B,0))<>"Completed"),FALSE()),"PENDING PREDECESSOR",IF($J20="At Risk","AT RISK",IF(OR($J20="Pending Approval",$J20="Pending Material"),UPPER($J20),IF($J20="In Progress","IN PROGRESS",IF($J20="Ready to Start","READY TO START","ON PLAN"))))))))) -> BLOCKED
A21: 11 | B21: 2.03 | C21: Phase 2 — Civil / Site Readiness | D21: Verification of available installation areas | E21: All trailers | F21: 1.08 | I21: =IF(OR($G21="",$H21=""),"TBD",$H21-$G21+1) -> TBD | J21: Not Started | K21: 0 | L21: TBC | M21: Site Supervisor | N21: TBC | O21: TBC | P21: Installation areas confirmed | Q21: — | R21: No | S21: Physical verification of clear areas for alarm and suppression equipment. | T21: =IF($H21="","TBD",IF($J21="Completed","Closed",$H21-TODAY())) -> TBD | U21: =IF($J21="Completed","COMPLETE",IF(AND($H21<>"",$H21<TODAY()),"OVERDUE",IF($J21="Blocked","BLOCKED",IF(ISNUMBER(SEARCH("Power availability",$P21)),"PENDING POWER AVAILABILITY",IF(IFERROR(IF($F21="—",FALSE(),INDEX($J:$J,MATCH($F21,$B:$B,0))<>"Completed"),FALSE()),"PENDING PREDECESSOR",IF($J21="At Risk","AT RISK",IF(OR($J21="Pending Approval",$J21="Pending Material"),UPPER($J21),IF($J21="In Progress","IN PROGRESS",IF($J21="Ready to Start","READY TO START","ON PLAN"))))))))) -> PENDING PREDECESSOR
A22: 12 | B22: 2.04 | C22: Phase 2 — Civil / Site Readiness | D22: Installation of Racks and Cabinets | E22: All trailers | F22: 2.03 | I22: =IF(OR($G22="",$H22=""),"TBD",$H22-$G22+1) -> TBD | J22: Not Started | K22: 0 | L22: TBC | M22: Main Contractor | N22: TBC | O22: TBC | P22: Installation areas verified | Q22: Racks and Cabinets installation not yet started | R22: No | S22: CONFIRMED (SURVEY): Installation of Racks and Cabinets has not yet started in the available trailers. | T22: =IF($H22="","TBD",IF($J22="Completed","Closed",$H22-TODAY())) -> TBD | U22: =IF($J22="Completed","COMPLETE",IF(AND($H22<>"",$H22<TODAY()),"OVERDUE",IF($J22="Blocked","BLOCKED",IF(ISNUMBER(SEARCH("Power availability",$P22)),"PENDING POWER AVAILABILITY",IF(IFERROR(IF($F22="—",FALSE(),INDEX($J:$J,MATCH($F22,$B:$B,0))<>"Completed"),FALSE()),"PENDING PREDECESSOR",IF($J22="At Risk","AT RISK",IF(OR($J22="Pending Approval",$J22="Pending Material"),UPPER($J22),IF($J22="In Progress","IN PROGRESS",IF($J22="Ready to Start","READY TO START","ON PLAN"))))))))) -> PENDING PREDECESSOR
A23: 13 | B23: 2.05 | C23: Phase 2 — Civil / Site Readiness | D23: Racks and Cabinets readiness confirmation / sign-off | E23: All trailers | F23: 2.04 | I23: =IF(OR($G23="",$H23=""),"TBD",$H23-$G23+1) -> TBD | J23: Not Started | K23: 0 | L23: TBC | M23: QA/QC | N23: TBC | O23: TBC | P23: Racks and Cabinets installation complete | Q23: Racks and Cabinets not yet started | R23: Yes | S23: Gate for all rack/cabinet-interfacing fire system activities. | T23: =IF($H23="","TBD",IF($J23="Completed","Closed",$H23-TODAY())) -> TBD | U23: =IF($J23="Completed","COMPLETE",IF(AND($H23<>"",$H23<TODAY()),"OVERDUE",IF($J23="Blocked","BLOCKED",IF(ISNUMBER(SEARCH("Power availability",$P23)),"PENDING POWER AVAILABILITY",IF(IFERROR(IF($F23="—",FALSE(),INDEX($J:$J,MATCH($F23,$B:$B,0))<>"Completed"),FALSE()),"PENDING PREDECESSOR",IF($J23="At Risk","AT RISK",IF(OR($J23="Pending Approval",$J23="Pending Material"),UPPER($J23),IF($J23="In Progress","IN PROGRESS",IF($J23="Ready to Start","READY TO START","ON PLAN"))))))))) -> PENDING PREDECESSOR
A24: 14 | B24: 2.06 | C24: Phase 2 — Civil / Site Readiness | D24: Power availability verification — trailers other than Trailer-2 | E24: All trailers | F24: 1.07 | I24: =IF(OR($G24="",$H24=""),"TBD",$H24-$G24+1) -> TBD | J24: Not Started | K24: 0 | L24: TBC | M24: Electrical Contractor | N24: TBC | O24: TBC | P24: Trailer availability confirmed | Q24: Survey confirms unavailability for Trailer-2 only; other trailers to be verified | R24: No | S24: Source confirms the power constraint for Trailer-2. Status of remaining trailers TBC. | T24: =IF($H24="","TBD",IF($J24="Completed","Closed",$H24-TODAY())) -> TBD | U24: =IF($J24="Completed","COMPLETE",IF(AND($H24<>"",$H24<TODAY()),"OVERDUE",IF($J24="Blocked","BLOCKED",IF(ISNUMBER(SEARCH("Power availability",$P24)),"PENDING POWER AVAILABILITY",IF(IFERROR(IF($F24="—",FALSE(),INDEX($J:$J,MATCH($F24,$B:$B,0))<>"Completed"),FALSE()),"PENDING PREDECESSOR",IF($J24="At Risk","AT RISK",IF(OR($J24="Pending Approval",$J24="Pending Material"),UPPER($J24),IF($J24="In Progress","IN PROGRESS",IF($J24="Ready to Start","READY TO START","ON PLAN"))))))))) -> PENDING PREDECESSOR
A25: 15 | B25: 2.07 | C25: Phase 2 — Civil / Site Readiness | D25: Access, HSE induction and work permit readiness | E25: All trailers | F25: 1.01 | I25: =IF(OR($G25="",$H25=""),"TBD",$H25-$G25+1) -> TBD | J25: Not Started | K25: 0 | L25: TBC | M25: HSE | N25: TBC | O25: TBC | P25: Kickoff complete | Q25: — | R25: Yes | S25: Permit-to-work regime, hot work and access control to be established. | T25: =IF($H25="","TBD",IF($J25="Completed","Closed",$H25-TODAY())) -> TBD | U25: =IF($J25="Completed","COMPLETE",IF(AND($H25<>"",$H25<TODAY()),"OVERDUE",IF($J25="Blocked","BLOCKED",IF(ISNUMBER(SEARCH("Power availability",$P25)),"PENDING POWER AVAILABILITY",IF(IFERROR(IF($F25="—",FALSE(),INDEX($J:$J,MATCH($F25,$B:$B,0))<>"Completed"),FALSE()),"PENDING PREDECESSOR",IF($J25="At Risk","AT RISK",IF(OR($J25="Pending Approval",$J25="Pending Material"),UPPER($J25),IF($J25="In Progress","IN PROGRESS",IF($J25="Ready to Start","READY TO START","ON PLAN"))))))))) -> PENDING PREDECESSOR
A26: Phase 3 — Engineering & Material Readiness · Proposed baseline: Week 2 – Week 8
A27: 16 | B27: 3.01 | C27: Phase 3 — Engineering & Material Readiness | D27: Fire suppression system design review | E27: All trailers | F27: 1.04 | I27: =IF(OR($G27="",$H27=""),"TBD",$H27-$G27+1) -> TBD | J27: Not Started | K27: 0 | L27: TBC | M27: Fire Suppression Engineer | N27: TBC | O27: TBC | P27: Scope confirmed | Q27: — | R27: No | S27: Design basis, agent type and coverage to be confirmed during engineering/design. | T27: =IF($H27="","TBD",IF($J27="Completed","Closed",$H27-TODAY())) -> TBD | U27: =IF($J27="Completed","COMPLETE",IF(AND($H27<>"",$H27<TODAY()),"OVERDUE",IF($J27="Blocked","BLOCKED",IF(ISNUMBER(SEARCH("Power availability",$P27)),"PENDING POWER AVAILABILITY",IF(IFERROR(IF($F27="—",FALSE(),INDEX($J:$J,MATCH($F27,$B:$B,0))<>"Completed"),FALSE()),"PENDING PREDECESSOR",IF($J27="At Risk","AT RISK",IF(OR($J27="Pending Approval",$J27="Pending Material"),UPPER($J27),IF($J27="In Progress","IN PROGRESS",IF($J27="Ready to Start","READY TO START","ON PLAN"))))))))) -> PENDING PREDECESSOR
A28: 17 | B28: 3.02 | C28: Phase 3 — Engineering & Material Readiness | D28: Fire alarm system design review | E28: All trailers | F28: 1.04 | I28: =IF(OR($G28="",$H28=""),"TBD",$H28-$G28+1) -> TBD | J28: Not Started | K28: 0 | L28: TBC | M28: Fire Alarm Engineer | N28: TBC | O28: TBC | P28: Scope confirmed | Q28: — | R28: No | S28: Detection philosophy and panel architecture to be confirmed during engineering/design. | T28: =IF($H28="","TBD",IF($J28="Completed","Closed",$H28-TODAY())) -> TBD | U28: =IF($J28="Completed","COMPLETE",IF(AND($H28<>"",$H28<TODAY()),"OVERDUE",IF($J28="Blocked","BLOCKED",IF(ISNUMBER(SEARCH("Power availability",$P28)),"PENDING POWER AVAILABILITY",IF(IFERROR(IF($F28="—",FALSE(),INDEX($J:$J,MATCH($F28,$B:$B,0))<>"Completed"),FALSE()),"PENDING PREDECESSOR",IF($J28="At Risk","AT RISK",IF(OR($J28="Pending Approval",$J28="Pending Material"),UPPER($J28),IF($J28="In Progress","IN PROGRESS",IF($J28="Ready to Start","READY TO START","ON PLAN"))))))))) -> PENDING PREDECESSOR
A29: 18 | B29: 3.03 | C29: Phase 3 — Engineering & Material Readiness | D29: Equipment and material confirmation | E29: All trailers | F29: 3.01 | I29: =IF(OR($G29="",$H29=""),"TBD",$H29-$G29+1) -> TBD | J29: Not Started | K29: 0 | L29: TBC | M29: Fire System Specialist | N29: TBC | O29: TBC | P29: Design reviews complete | Q29: — | R29: No | S29: Equipment types not specified in the survey — to be confirmed during engineering/design. | T29: =IF($H29="","TBD",IF($J29="Completed","Closed",$H29-TODAY())) -> TBD | U29: =IF($J29="Completed","COMPLETE",IF(AND($H29<>"",$H29<TODAY()),"OVERDUE",IF($J29="Blocked","BLOCKED",IF(ISNUMBER(SEARCH("Power availability",$P29)),"PENDING POWER AVAILABILITY",IF(IFERROR(IF($F29="—",FALSE(),INDEX($J:$J,MATCH($F29,$B:$B,0))<>"Completed"),FALSE()),"PENDING PREDECESSOR",IF($J29="At Risk","AT RISK",IF(OR($J29="Pending Approval",$J29="Pending Material"),UPPER($J29),IF($J29="In Progress","IN PROGRESS",IF($J29="Ready to Start","READY TO START","ON PLAN"))))))))) -> PENDING PREDECESSOR
A30: 19 | B30: 3.04 | C30: Phase 3 — Engineering & Material Readiness | D30: Shop drawing and technical submittal preparation | E30: All trailers | F30: 3.03 | I30: =IF(OR($G30="",$H30=""),"TBD",$H30-$G30+1) -> TBD | J30: Not Started | K30: 0 | L30: TBC | M30: Fire System Specialist | N30: TBC | O30: TBC | P30: Material list confirmed | Q30: — | R30: No | S30: Submittal package covering both recommended systems. | T30: =IF($H30="","TBD",IF($J30="Completed","Closed",$H30-TODAY())) -> TBD | U30: =IF($J30="Completed","COMPLETE",IF(AND($H30<>"",$H30<TODAY()),"OVERDUE",IF($J30="Blocked","BLOCKED",IF(ISNUMBER(SEARCH("Power availability",$P30)),"PENDING POWER AVAILABILITY",IF(IFERROR(IF($F30="—",FALSE(),INDEX($J:$J,MATCH($F30,$B:$B,0))<>"Completed"),FALSE()),"PENDING PREDECESSOR",IF($J30="At Risk","AT RISK",IF(OR($J30="Pending Approval",$J30="Pending Material"),UPPER($J30),IF($J30="In Progress","IN PROGRESS",IF($J30="Ready to Start","READY TO START","ON PLAN"))))))))) -> PENDING PREDECESSOR
A31: 20 | B31: 3.05 | C31: Phase 3 — Engineering & Material Readiness | D31: Shop drawing and material approval | E31: All trailers | F31: 3.04 | I31: =IF(OR($G31="",$H31=""),"TBD",$H31-$G31+1) -> TBD | J31: Pending Approval | K31: 0 | L31: TBC | M31: Client Representative | N31: TBC | O31: TBC | P31: Submittal issued | Q31: Approval turnaround not yet agreed | R31: Yes | S31: Approving authority and review duration to be confirmed. | T31: =IF($H31="","TBD",IF($J31="Completed","Closed",$H31-TODAY())) -> TBD | U31: =IF($J31="Completed","COMPLETE",IF(AND($H31<>"",$H31<TODAY()),"OVERDUE",IF($J31="Blocked","BLOCKED",IF(ISNUMBER(SEARCH("Power availability",$P31)),"PENDING POWER AVAILABILITY",IF(IFERROR(IF($F31="—",FALSE(),INDEX($J:$J,MATCH($F31,$B:$B,0))<>"Completed"),FALSE()),"PENDING PREDECESSOR",IF($J31="At Risk","AT RISK",IF(OR($J31="Pending Approval",$J31="Pending Material"),UPPER($J31),IF($J31="In Progress","IN PROGRESS",IF($J31="Ready to Start","READY TO START","ON PLAN"))))))))) -> PENDING PREDECESSOR
A32: 21 | B32: 3.06 | C32: Phase 3 — Engineering & Material Readiness | D32: Procurement and purchase order release | E32: All trailers | F32: 3.05 | I32: =IF(OR($G32="",$H32=""),"TBD",$H32-$G32+1) -> TBD | J32: Pending Material | K32: 0 | L32: TBC | M32: Main Contractor | N32: TBC | O32: TBC | P32: Material approval obtained | Q32: Long-lead items may drive the critical path | R32: Yes | S32: Lead times unknown until equipment selection is confirmed. | T32: =IF($H32="","TBD",IF($J32="Completed","Closed",$H32-TODAY())) -> TBD | U32: =IF($J32="Completed","COMPLETE",IF(AND($H32<>"",$H32<TODAY()),"OVERDUE",IF($J32="Blocked","BLOCKED",IF(ISNUMBER(SEARCH("Power availability",$P32)),"PENDING POWER AVAILABILITY",IF(IFERROR(IF($F32="—",FALSE(),INDEX($J:$J,MATCH($F32,$B:$B,0))<>"Completed"),FALSE()),"PENDING PREDECESSOR",IF($J32="At Risk","AT RISK",IF(OR($J32="Pending Approval",$J32="Pending Material"),UPPER($J32),IF($J32="In Progress","IN PROGRESS",IF($J32="Ready to Start","READY TO START","ON PLAN"))))))))) -> PENDING PREDECESSOR
A33: 22 | B33: 3.07 | C33: Phase 3 — Engineering & Material Readiness | D33: Manufacturing, delivery to site and material inspection | E33: All trailers | F33: 3.06 | I33: =IF(OR($G33="",$H33=""),"TBD",$H33-$G33+1) -> TBD | J33: Pending Material | K33: 0 | L33: TBC | M33: Main Contractor | N33: TBC | O33: TBC | P33: Purchase orders placed | Q33: Delivery lead time TBC | R33: No | S33: Material availability is a gate for the start of Phase 4. | T33: =IF($H33="","TBD",IF($J33="Completed","Closed",$H33-TODAY())) -> TBD | U33: =IF($J33="Completed","COMPLETE",IF(AND($H33<>"",$H33<TODAY()),"OVERDUE",IF($J33="Blocked","BLOCKED",IF(ISNUMBER(SEARCH("Power availability",$P33)),"PENDING POWER AVAILABILITY",IF(IFERROR(IF($F33="—",FALSE(),INDEX($J:$J,MATCH($F33,$B:$B,0))<>"Completed"),FALSE()),"PENDING PREDECESSOR",IF($J33="At Risk","AT RISK",IF(OR($J33="Pending Approval",$J33="Pending Material"),UPPER($J33),IF($J33="In Progress","IN PROGRESS",IF($J33="Ready to Start","READY TO START","ON PLAN"))))))))) -> PENDING PREDECESSOR
A34: Phase 4 — Installation · Proposed baseline: Week 8 – Week 12
A35: 23 | B35: 4.01 | C35: Phase 4 — Installation | D35: Fire alarm system installation — containment and cabling | E35: All trailers | F35: 3.07 | I35: =IF(OR($G35="",$H35=""),"TBD",$H35-$G35+1) -> TBD | J35: Not Started | K35: 0 | L35: TBC | M35: Fire System Specialist | N35: TBC | O35: TBC | P35: Material on site + Racks and Cabinets ready (2.05) | Q35: Racks and Cabinets installation not yet started | R35: No | S35: First installation front; cannot start before site readiness gates are closed. | T35: =IF($H35="","TBD",IF($J35="Completed","Closed",$H35-TODAY())) -> TBD | U35: =IF($J35="Completed","COMPLETE",IF(AND($H35<>"",$H35<TODAY()),"OVERDUE",IF($J35="Blocked","BLOCKED",IF(ISNUMBER(SEARCH("Power availability",$P35)),"PENDING POWER AVAILABILITY",IF(IFERROR(IF($F35="—",FALSE(),INDEX($J:$J,MATCH($F35,$B:$B,0))<>"Completed"),FALSE()),"PENDING PREDECESSOR",IF($J35="At Risk","AT RISK",IF(OR($J35="Pending Approval",$J35="Pending Material"),UPPER($J35),IF($J35="In Progress","IN PROGRESS",IF($J35="Ready to Start","READY TO START","ON PLAN"))))))))) -> PENDING PREDECESSOR
A36: 24 | B36: 4.02 | C36: Phase 4 — Installation | D36: Fire detection devices installation | E36: All trailers | F36: 4.01 | I36: =IF(OR($G36="",$H36=""),"TBD",$H36-$G36+1) -> TBD | J36: Not Started | K36: 0 | L36: TBC | M36: Fire Alarm Engineer | N36: TBC | O36: TBC | P36: Containment and cabling complete | Q36: — | R36: No | S36: Device types to be confirmed during engineering/design. | T36: =IF($H36="","TBD",IF($J36="Completed","Closed",$H36-TODAY())) -> TBD | U36: =IF($J36="Completed","COMPLETE",IF(AND($H36<>"",$H36<TODAY()),"OVERDUE",IF($J36="Blocked","BLOCKED",IF(ISNUMBER(SEARCH("Power availability",$P36)),"PENDING POWER AVAILABILITY",IF(IFERROR(IF($F36="—",FALSE(),INDEX($J:$J,MATCH($F36,$B:$B,0))<>"Completed"),FALSE()),"PENDING PREDECESSOR",IF($J36="At Risk","AT RISK",IF(OR($J36="Pending Approval",$J36="Pending Material"),UPPER($J36),IF($J36="In Progress","IN PROGRESS",IF($J36="Ready to Start","READY TO START","ON PLAN"))))))))) -> PENDING PREDECESSOR
A37: 25 | B37: 4.03 | C37: Phase 4 — Installation | D37: Fire alarm control and monitoring equipment installation | E37: All trailers | F37: 4.01 | I37: =IF(OR($G37="",$H37=""),"TBD",$H37-$G37+1) -> TBD | J37: Not Started | K37: 0 | L37: TBC | M37: Fire Alarm Engineer | N37: TBC | O37: TBC | P37: Containment and cabling complete | Q37: — | R37: No | S37: Control/monitoring equipment scope to be confirmed during engineering/design. | T37: =IF($H37="","TBD",IF($J37="Completed","Closed",$H37-TODAY())) -> TBD | U37: =IF($J37="Completed","COMPLETE",IF(AND($H37<>"",$H37<TODAY()),"OVERDUE",IF($J37="Blocked","BLOCKED",IF(ISNUMBER(SEARCH("Power availability",$P37)),"PENDING POWER AVAILABILITY",IF(IFERROR(IF($F37="—",FALSE(),INDEX($J:$J,MATCH($F37,$B:$B,0))<>"Completed"),FALSE()),"PENDING PREDECESSOR",IF($J37="At Risk","AT RISK",IF(OR($J37="Pending Approval",$J37="Pending Material"),UPPER($J37),IF($J37="In Progress","IN PROGRESS",IF($J37="Ready to Start","READY TO START","ON PLAN"))))))))) -> PENDING PREDECESSOR
A38: 26 | B38: 4.04 | C38: Phase 4 — Installation | D38: Fire suppression system installation — mounting and supports | E38: All trailers | F38: 3.07 | I38: =IF(OR($G38="",$H38=""),"TBD",$H38-$G38+1) -> TBD | J38: Not Started | K38: 0 | L38: TBC | M38: Fire Suppression Engineer | N38: TBC | O38: TBC | P38: Material on site + Racks and Cabinets ready (2.05) | Q38: Racks and Cabinets installation not yet started | R38: No | S38: Suppression system recommended by the survey; configuration TBC in design. | T38: =IF($H38="","TBD",IF($J38="Completed","Closed",$H38-TODAY())) -> TBD | U38: =IF($J38="Completed","COMPLETE",IF(AND($H38<>"",$H38<TODAY()),"OVERDUE",IF($J38="Blocked","BLOCKED",IF(ISNUMBER(SEARCH("Power availability",$P38)),"PENDING POWER AVAILABILITY",IF(IFERROR(IF($F38="—",FALSE(),INDEX($J:$J,MATCH($F38,$B:$B,0))<>"Completed"),FALSE()),"PENDING PREDECESSOR",IF($J38="At Risk","AT RISK",IF(OR($J38="Pending Approval",$J38="Pending Material"),UPPER($J38),IF($J38="In Progress","IN PROGRESS",IF($J38="Ready to Start","READY TO START","ON PLAN"))))))))) -> PENDING PREDECESSOR
A39: 27 | B39: 4.05 | C39: Phase 4 — Installation | D39: Suppression equipment installation | E39: All trailers | F39: 4.04 | I39: =IF(OR($G39="",$H39=""),"TBD",$H39-$G39+1) -> TBD | J39: Not Started | K39: 0 | L39: TBC | M39: Fire Suppression Engineer | N39: TBC | O39: TBC | P39: Mounting and supports complete | Q39: — | R39: No | S39: Equipment types to be confirmed during engineering/design. | T39: =IF($H39="","TBD",IF($J39="Completed","Closed",$H39-TODAY())) -> TBD | U39: =IF($J39="Completed","COMPLETE",IF(AND($H39<>"",$H39<TODAY()),"OVERDUE",IF($J39="Blocked","BLOCKED",IF(ISNUMBER(SEARCH("Power availability",$P39)),"PENDING POWER AVAILABILITY",IF(IFERROR(IF($F39="—",FALSE(),INDEX($J:$J,MATCH($F39,$B:$B,0))<>"Completed"),FALSE()),"PENDING PREDECESSOR",IF($J39="At Risk","AT RISK",IF(OR($J39="Pending Approval",$J39="Pending Material"),UPPER($J39),IF($J39="In Progress","IN PROGRESS",IF($J39="Ready to Start","READY TO START","ON PLAN"))))))))) -> PENDING PREDECESSOR
A40: 28 | B40: 4.06 | C40: Phase 4 — Installation | D40: Piping / tubing and associated components installation (where applicable) | E40: All trailers | F40: 4.05 | I40: =IF(OR($G40="",$H40=""),"TBD",$H40-$G40+1) -> TBD | J40: Not Started | K40: 0 | L40: TBC | M40: Fire Suppression Engineer | N40: TBC | O40: TBC | P40: Suppression equipment installed | Q40: — | R40: No | S40: Applicability depends on the suppression solution confirmed during design. | T40: =IF($H40="","TBD",IF($J40="Completed","Closed",$H40-TODAY())) -> TBD | U40: =IF($J40="Completed","COMPLETE",IF(AND($H40<>"",$H40<TODAY()),"OVERDUE",IF($J40="Blocked","BLOCKED",IF(ISNUMBER(SEARCH("Power availability",$P40)),"PENDING POWER AVAILABILITY",IF(IFERROR(IF($F40="—",FALSE(),INDEX($J:$J,MATCH($F40,$B:$B,0))<>"Completed"),FALSE()),"PENDING PREDECESSOR",IF($J40="At Risk","AT RISK",IF(OR($J40="Pending Approval",$J40="Pending Material"),UPPER($J40),IF($J40="In Progress","IN PROGRESS",IF($J40="Ready to Start","READY TO START","ON PLAN"))))))))) -> PENDING PREDECESSOR
A41: 29 | B41: 4.07 | C41: Phase 4 — Installation | D41: Interfaces with racks and cabinets | E41: All trailers | F41: 2.05 | I41: =IF(OR($G41="",$H41=""),"TBD",$H41-$G41+1) -> TBD | J41: Not Started | K41: 0 | L41: TBC | M41: Fire System Specialist | N41: TBC | O41: TBC | P41: Racks and Cabinets ready (2.05) | Q41: Racks and Cabinets installation not yet started | R41: No | S41: Directly gated by the rack/cabinet readiness constraint recorded in the survey. | T41: =IF($H41="","TBD",IF($J41="Completed","Closed",$H41-TODAY())) -> TBD | U41: =IF($J41="Completed","COMPLETE",IF(AND($H41<>"",$H41<TODAY()),"OVERDUE",IF($J41="Blocked","BLOCKED",IF(ISNUMBER(SEARCH("Power availability",$P41)),"PENDING POWER AVAILABILITY",IF(IFERROR(IF($F41="—",FALSE(),INDEX($J:$J,MATCH($F41,$B:$B,0))<>"Completed"),FALSE()),"PENDING PREDECESSOR",IF($J41="At Risk","AT RISK",IF(OR($J41="Pending Approval",$J41="Pending Material"),UPPER($J41),IF($J41="In Progress","IN PROGRESS",IF($J41="Ready to Start","READY TO START","ON PLAN"))))))))) -> PENDING PREDECESSOR
A42: 30 | B42: 4.08 | C42: Phase 4 — Installation | D42: Power and control connections | E42: Trailer-2 / All trailers | F42: 2.02 | I42: =IF(OR($G42="",$H42=""),"TBD",$H42-$G42+1) -> TBD | J42: Blocked | K42: 0 | L42: TBC | M42: Electrical Contractor | N42: TBC | O42: TBC | P42: Completion of partition works + Power availability confirmation (Trailer-2) | Q42: Trailer-2 power source currently unavailable | R42: No | S42: CONFIRMED (SURVEY): Cannot proceed in Trailer-2 until partition works finish and power is available. | T42: =IF($H42="","TBD",IF($J42="Completed","Closed",$H42-TODAY())) -> TBD | U42: =IF($J42="Completed","COMPLETE",IF(AND($H42<>"",$H42<TODAY()),"OVERDUE",IF($J42="Blocked","BLOCKED",IF(ISNUMBER(SEARCH("Power availability",$P42)),"PENDING POWER AVAILABILITY",IF(IFERROR(IF($F42="—",FALSE(),INDEX($J:$J,MATCH($F42,$B:$B,0))<>"Completed"),FALSE()),"PENDING PREDECESSOR",IF($J42="At Risk","AT RISK",IF(OR($J42="Pending Approval",$J42="Pending Material"),UPPER($J42),IF($J42="In Progress","IN PROGRESS",IF($J42="Ready to Start","READY TO START","ON PLAN"))))))))) -> BLOCKED
...

Sheet 3. Gantt Chart
A1: FIRE FIGHTING SYSTEM — NEW DC
A2: Installation Schedule & Project Responsibility Tracker
A3: Survey Date: 30-Jun-2026 | PM: Kharsan Mujeb Al Ajmi | [OFFICIAL LOGO — TO BE INSERTED]
A5: PROPOSED BASELINE — DATES TO BE CONFIRMED. The timeline below is relative (Week 1 = project kickoff). It is NOT a calendar schedule. Proposed planning dates are preliminary and subject to confirmation by the Project Owner, PM, Contractor and relevant stakeholders.
A6: LEGEND | J6: Preparation | P6: Site Readiness | V6: Engineering
J7: Installation | P7: Testing & Commissioning | V7: Handover
J8: Critical activity | P8: Trailer-2 power dependency
A10: ID | B10: WBS | C10: Activity | D10: Phase | E10: Critical / Dependency | F10: Prede- cessor | G10: Baseline Wk Start | H10: Baseline Wk Finish | I10: 1 | J10: 2 | K10: 3 | L10: 4 | M10: 5 | N10: 6 | O10: 7 | P10: 8 | Q10: 9 | R10: 10 | S10: 11 | T10: 12 | U10: 13 | V10: 14 | W10: 15 | X10: 16 | Y10: 17 | Z10: 18
A11: Phase 1 — Project Preparation | D11: Preparation | E11: PHASE ENVELOPE | F11: — | G11: 1 | H11: 2
A12: 1 | B12: 1.01 | C12: Project kickoff meeting and baseline agreement | D12: Preparation | E12: — | F12: — | G12: 1 | H12: 1
A13: 2 | B13: 1.02 | C13: Site survey execution — RC Vehicle Survey | D13: Preparation | E13: — | F13: —
A14: 3 | B14: 1.03 | C14: Review of RC Vehicle Survey Report dated 30-Jun-2026 | D14: Preparation | E14: — | F14: 1.02 | G14: 1 | H14: 1
A15: 4 | B15: 1.04 | C15: Scope confirmation — Fire Alarm System and Fire Suppression System | D15: Preparation | E15: — | F15: 1.03 | G15: 1 | H15: 2
A16: 5 | B16: 1.05 | C16: Confirmation of project stakeholders, owner and governance | D16: Preparation | E16: — | F16: 1.01 | G16: 1 | H16: 2
A17: 6 | B17: 1.06 | C17: Site readiness verification walkdown | D17: Preparation | E17: — | F17: 1.04 | G17: 2 | H17: 2
A18: 7 | B18: 1.07 | C18: Confirmation of trailer availability | D18: Preparation | E18: — | F18: 1.06 | G18: 2 | H18: 2
A19: 8 | B19: 1.08 | C19: Confirmation of installation areas within trailers | D19: Preparation | E19: — | F19: 1.07 | G19: 2 | H19: 2
A20: Phase 2 — Civil / Site Readiness | D20: Site Readiness | E20: PHASE ENVELOPE | F20: — | G20: 1 | H20: 6
A21: 9 | B21: 2.01 | C21: Completion of partition works | D21: Site Readiness | E21: CRITICAL | F21: — | G21: 1 | H21: 4
A22: 10 | B22: 2.02 | C22: Power source availability verification and energisation | D22: Site Readiness | E22: T2 POWER | F22: 2.01 | G22: 4 | H22: 5
A23: 11 | B23: 2.03 | C23: Verification of available installation areas | D23: Site Readiness | E23: — | F23: 1.08 | G23: 2 | H23: 3
A24: 12 | B24: 2.04 | C24: Installation of Racks and Cabinets | D24: Site Readiness | E24: CRITICAL | F24: 2.03 | G24: 3 | H24: 6
A25: 13 | B25: 2.05 | C25: Racks and Cabinets readiness confirmation / sign-off | D25: Site Readiness | E25: CRITICAL | F25: 2.04 | G25: 6 | H25: 6
A26: 14 | B26: 2.06 | C26: Power availability verification — trailers other than Trailer-2 | D26: Site Readiness | E26: — | F26: 1.07 | G26: 2 | H26: 3
A27: 15 | B27: 2.07 | C27: Access, HSE induction and work permit readiness | D27: Site Readiness | E27: — | F27: 1.01 | G27: 2 | H27: 3
A28: Phase 3 — Engineering & Material Readiness | D28: Engineering | E28: PHASE ENVELOPE | F28: — | G28: 2 | H28: 8
A29: 16 | B29: 3.01 | C29: Fire suppression system design review | D29: Engineering | E29: — | F29: 1.04 | G29: 2 | H29: 3
A30: 17 | B30: 3.02 | C30: Fire alarm system design review | D30: Engineering | E30: — | F30: 1.04 | G30: 2 | H30: 3
A31: 18 | B31: 3.03 | C31: Equipment and material confirmation | D31: Engineering | E31: — | F31: 3.01 | G31: 3 | H31: 4
A32: 19 | B32: 3.04 | C32: Shop drawing and technical submittal preparation | D32: Engineering | E32: — | F32: 3.03 | G32: 3 | H32: 4
A33: 20 | B33: 3.05 | C33: Shop drawing and material approval | D33: Engineering | E33: CRITICAL | F33: 3.04 | G33: 5 | H33: 5
A34: 21 | B34: 3.06 | C34: Procurement and purchase order release | D34: Engineering | E34: CRITICAL | F34: 3.05 | G34: 5 | H34: 6
A35: 22 | B35: 3.07 | C35: Manufacturing, delivery to site and material inspection | D35: Engineering | E35: CRITICAL | F35: 3.06 | G35: 6 | H35: 8
A36: Phase 4 — Installation | D36: Installation | E36: PHASE ENVELOPE | F36: — | G36: 8 | H36: 12
A37: 23 | B37: 4.01 | C37: Fire alarm system installation — containment and cabling | D37: Installation | E37: CRITICAL | F37: 3.07 | G37: 8 | H37: 9
A38: 24 | B38: 4.02 | C38: Fire detection devices installation | D38: Installation | E38: — | F38: 4.01 | G38: 9 | H38: 10
A39: 25 | B39: 4.03 | C39: Fire alarm control and monitoring equipment installation | D39: Installation | E39: — | F39: 4.01 | G39: 9 | H39: 10
A40: 26 | B40: 4.04 | C40: Fire suppression system installation — mounting and supports | D40: Installation | E40: CRITICAL | F40: 3.07 | G40: 8 | H40: 10
A41: 27 | B41: 4.05 | C41: Suppression equipment installation | D41: Installation | E41: — | F41: 4.04 | G41: 10 | H41: 11
A42: 28 | B42: 4.06 | C42: Piping / tubing and associated components installation (where applicable) | D42: Installation | E42: — | F42: 4.05 | G42: 10 | H42: 11
...

Sheet 4. Responsibility Matrix
A1: FIRE FIGHTING SYSTEM — NEW DC
A2: Installation Schedule & Project Responsibility Tracker
A3: Survey Date: 30-Jun-2026 | PM: Kharsan Mujeb Al Ajmi | [OFFICIAL LOGO — TO BE INSERTED]
A5: The only person identified in the source survey report is Kharsan Mujeb Al Ajmi (Project Manager). All other names are marked TBC — To Be Confirmed. Names and contact details are editable fields for the project team to complete; no names have been assumed.
A7: PROJECT GOVERNANCE — editable
A8: Project Owner | B8: TBC | D8: Enter the confirmed name here once appointed.
A9: Project Manager | B9: Kharsan Mujeb Al Ajmi | D9: Confirmed by the source survey report.
A10: Main Contractor | B10: TBC | D10: Enter the confirmed name here once appointed.
A11: Fire System Contractor | B11: TBC | D11: Enter the confirmed name here once appointed.
A12: Client Representative | B12: TBC | D12: Enter the confirmed name here once appointed.
A13: QA/QC | B13: TBC | D13: Enter the confirmed name here once appointed.
A14: HSE | B14: TBC | D14: Enter the confirmed name here once appointed.
A16: PROJECT RESPONSIBILITY MATRIX
A18: Responsibility Area | B18: Name | C18: Role | D18: Organization / Contractor | E18: Responsibility | F18: Contact | G18: Status
A19: Project Ownership | B19: TBC | C19: Project Owner | D19: TBC | E19: Overall accountability, funding, acceptance and handover authority. | F19: TBC | G19: Not Started
A20: Project Management | B20: Kharsan Mujeb Al Ajmi | C20: Project Manager | D20: TBC | E20: Day-to-day management, schedule, reporting and stakeholder coordination. | F20: TBC | G20: In Progress
A21: Fire & Life Safety | B21: TBC | C21: Fire & Life Safety Engineer | D21: TBC | E21: Design compliance, integration and life-safety assurance. | F21: TBC | G21: Not Started
A22: Fire Alarm Engineering | B22: TBC | C22: Fire Alarm Engineer | D22: TBC | E22: Fire alarm design review, installation supervision and testing. | F22: TBC | G22: Not Started
A23: Fire Suppression Engineering | B23: TBC | C23: Fire Suppression Engineer | D23: TBC | E23: Fire suppression design review, installation supervision and testing. | F23: TBC | G23: Not Started
A24: Site Supervision | B24: TBC | C24: Site Supervisor | D24: TBC | E24: Daily site control, work fronts, coordination between trades. | F24: TBC | G24: Not Started
A25: Main Works | B25: TBC | C25: Main Contractor | D25: TBC | E25: Overall construction delivery including racks and cabinets installation. | F25: TBC | G25: Not Started
A26: Fire System Delivery | B26: TBC | C26: Fire System Specialist | D26: TBC | E26: Supply and installation of the recommended fire alarm and suppression systems. | F26: TBC | G26: Not Started
A27: Electrical Works | B27: TBC | C27: Electrical Contractor | D27: TBC | E27: Power supply, energisation and power/control connections. | F27: TBC | G27: Not Started
A28: Civil / Partition Works | B28: TBC | C28: Civil / Partition Contractor | D28: TBC | E28: Partition works in Trailer-2 — currently ongoing per survey. | F28: TBC | G28: In Progress
A29: Quality Assurance | B29: TBC | C29: QA/QC | D29: TBC | E29: Inspection, ITP execution, punch list management and sign-off. | F29: TBC | G29: Not Started
... A32: Client Interface | B32: TBC | C32: Client Representative | D32: TBC | E32: Approvals, witnessing, final acceptance and handover receipt. | F32: TBC | G32: Not Started
A34: TBC — To Be Confirmed. Shaded cells are editable fields for the project team.

Sheet 5. Action Tracker
A1: FIRE FIGHTING SYSTEM — NEW DC
A2: Installation Schedule & Project Responsibility Tracker
A3: Survey Date: 30-Jun-2026 | PM: Kharsan Mujeb Al Ajmi | [OFFICIAL LOGO — TO BE INSERTED]
A5: MANAGEMENT ACTION TRACKER — actions ordered by their ability to delay installation. Critical path sequence: complete partition works in Trailer-2 → confirm power availability → complete racks and cabinets → confirm site readiness → release installation activities. Due dates are TBD until the baseline is confirmed.
A7: Action ID | B7: Required Action | C7: Reason | D7: Responsible | E7: Due Date | F7: Priority | G7: Status | H7: Escalation Required | I7: Remarks
A8: A01 | B8: Complete partition works in Trailer-2 | C8: Survey confirms partition works are still ongoing, which is blocking the power source. | D8: Civil / Partition Contractor (TBC) | E8: TBD | F8: Critical | G8: In Progress | H8: Yes | I8: CRITICAL PATH — first link in the Trailer-2 readiness chain.
A9: A02 | B9: Confirm power availability in Trailer-2 once partitions are complete | C9: Survey confirms the Trailer-2 power source is currently unavailable. | D9: Electrical Contractor (TBC) | E9: TBD | F9: Critical | G9: Blocked | H9: Yes | I9: CRITICAL PATH — gates power and control connections and functional testing.
A10: A03 | B10: Start and complete installation of Racks and Cabinets | C10: Survey confirms rack and cabinet installation has not yet started in the available trailers. | D10: Main Contractor (TBC) | E10: TBD | F10: Critical | G10: Not Started | H10: Yes | I10: CRITICAL PATH — gates all rack/cabinet-interfacing fire system works.
A11: A04 | B11: Confirm overall site readiness and release installation work fronts | C11: Installation cannot be released until partitions, power and racks/cabinets are confirmed ready. | D11: Project Manager — Kharsan Mujeb Al Ajmi | E11: TBD | F11: Critical | G11: Not Started | H11: Yes | I11: Sequence: A01 → A02 → A03 → A04 → release Phase 4.
A12: A05 | B12: Nominate the Project Owner and confirm the governance structure | C12: No project owner is identified in the source document; approvals cannot be routed. | D12: Project Manager — Kharsan Mujeb Al Ajmi | E12: TBD | F12: High | G12: Not Started | H12: Yes | I12: Required before any approval-gated activity can complete.
A13: A06 | B13: Appoint the Main Contractor and Fire System Contractor | C13: No contractor is named in the source document. | D13: Project Owner (TBC) | E13: TBD | F13: High | G13: Not Started | H13: Yes | I13: Required to resource Phases 2 to 6.
A14: A07 | B14: Confirm fire alarm and fire suppression design basis and equipment selection | C14: The survey recommends both systems but does not specify equipment types. | D14: Fire & Life Safety Engineer (TBC) | E14: TBD | F14: High | G14: Not Started | H14: No | I14: Equipment types to be confirmed during engineering/design.
A15: A08 | B15: Establish and approve the project baseline dates | C15: The source document provides no start, duration or completion dates. | D15: Project Manager — Kharsan Mujeb Al Ajmi | E15: TBD | F15: High | G15: Not Started | H15: No | I15: Converts the proposed relative baseline into confirmed calendar dates.
A16: A09 | B16: Confirm procurement lead times for the approved materials | C16: Long-lead items may govern the installation start date. | D16: Main Contractor (TBC) | E16: TBD | F16: Medium | G16: Not Started | H16: No | I16: Feeds milestone M06 — Materials Available on Site.
A17: A10 | B17: Confirm the power availability status of all trailers other than Trailer-2 | C17: The survey confirms the constraint for Trailer-2 only; other trailers are not addressed. | D17: Electrical Contractor (TBC) | E17: TBD | F17: Medium | G17: Not Started | H17: No | I17: Closes an open information gap in the source document.
A18: A11 | B18: Establish the permit-to-work and HSE regime for trailer works | C18: Work cannot commence without access and permit readiness. | D18: HSE (TBC) | E18: TBD | F18: Medium | G18: Not Started | H18: No | I18: Prerequisite for all site work fronts.
A19: A12 | B19: Agree the approval authority and review turnaround for submittals | C19: Approval route is undefined, which puts the engineering gate at risk. | D19: Client Representative (TBC) | E19: TBD | F19: Medium | G19: Not Started | H19: No | I19: Feeds milestone M05 — Engineering Approved.
A21: Actions A01–A04 form the critical path to releasing installation. Shaded Due Date cells are editable.

Sheet 6. Risk Register
A1: FIRE FIGHTING SYSTEM — NEW DC
A2: Installation Schedule & Project Responsibility Tracker
A3: Survey Date: 30-Jun-2026 | PM: Kharsan Mujeb Al Ajmi | [OFFICIAL LOGO — TO BE INSERTED]
A5: Risks R01 and R02 are the constraints explicitly recorded in the source survey report. All remaining entries are standard project-planning risks and are labelled “Planning Risk — To Be Validated”. Probability, Severity and Status are drop-down lists; the Risk Rating column calculates automatically.
A7: Risk ID | B7: Risk | C7: Cause | D7: Impact | E7: Probability | F7: Severity | G7: Mitigation | H7: Owner | I7: Target Date | J7: Status | K7: Risk Rating (auto) | L7: Classification
A8: R01 | B8: Trailer-2 power source remains unavailable | C8: Partition works in Trailer-2 are still ongoing (confirmed by survey). | D8: Power and control connections, functional testing and Trailer-2 handover cannot proceed. | E8: High | F8: High | G8: Expedite partition works; agree a firm completion date; confirm energisation plan; consider a temporary certified supply if approved. | H8: Civil / Partition Contractor (TBC) | I8: TBD | J8: Open | K8: =IF(OR($E8="",$F8="",$E8="TBC",$F8="TBC"),"TBC",IF(AND($E8="High",$F8="High"),"CRITICAL",IF(OR(AND($E8="High",$F8="Medium"),AND($E8="Medium",$F8="High")),"HIGH",IF(AND($E8="Low",$F8="Low"),"LOW","MEDIUM")))) -> CRITICAL | L8: Source-confirmed constraint
A9: R02 | B9: Racks and Cabinets installation has not started | C9: Rack and cabinet works not yet commenced in the available trailers (confirmed by survey). | D9: All rack/cabinet-interfacing fire alarm and suppression activities are gated; installation start slips. | E9: High | F9: High | G9: Confirm rack/cabinet scope, contractor and start date; sequence rack installation ahead of fire system works. | H9: Main Contractor (TBC) | I9: TBD | J9: Open | K9: =IF(OR($E9="",$F9="",$E9="TBC",$F9="TBC"),"TBC",IF(AND($E9="High",$F9="High"),"CRITICAL",IF(OR(AND($E9="High",$F9="Medium"),AND($E9="Medium",$F9="High")),"HIGH",IF(AND($E9="Low",$F9="Low"),"LOW","MEDIUM")))) -> CRITICAL | L9: Source-confirmed constraint
A10: R03 | B10: No confirmed project baseline dates | C10: The source document provides no start, duration or completion dates. | D10: Progress cannot be measured; delay cannot be evidenced; no contractual float visibility. | E10: High | F10: Medium | G10: Convert the proposed relative baseline into calendar dates at kickoff and freeze as Version 1.0. | H10: Project Manager — Kharsan Mujeb Al Ajmi | I10: TBD | J10: Open | K10: =IF(OR($E10="",$F10="",$E10="TBC",$F10="TBC"),"TBC",IF(AND($E10="High",$F10="High"),"CRITICAL",IF(OR(AND($E10="High",$F10="Medium"),AND($E10="Medium",$F10="High")),"HIGH",IF(AND($E10="Low",$F10="Low"),"LOW","MEDIUM")))) -> HIGH | L10: Planning Risk — To Be Validated
A11: R04 | B11: Project Owner and contractors not yet appointed | C11: No owner or contractor is identified in the source document. | D11: Approvals stall; no accountable party for the critical path actions. | E11: High | F11: Medium | G11: Nominate the Project Owner and award the main and fire system packages before Phase 3 approvals. | H11: Project Owner (TBC) | I11: TBD | J11: Open | K11: =IF(OR($E11="",$F11="",$E11="TBC",$F11="TBC"),"TBC",IF(AND($E11="High",$F11="High"),"CRITICAL",IF(OR(AND($E11="High",$F11="Medium"),AND($E11="Medium",$F11="High")),"HIGH",IF(AND($E11="Low",$F11="Low"),"LOW","MEDIUM")))) -> HIGH | L11: Planning Risk — To Be Validated
A12: R05 | B12: Equipment selection not yet defined | C12: The survey recommends the systems but does not specify equipment types. | D12: Procurement cannot start; lead times remain unknown; installation start date unreliable. | E12: Medium | F12: High | G12: Complete design reviews and freeze the material schedule before releasing purchase orders. | H12: Fire & Life Safety Engineer (TBC) | I12: TBD | J12: Open | K12: =IF(OR($E12="",$F12="",$E12="TBC",$F12="TBC"),"TBC",IF(AND($E12="High",$F12="High"),"CRITICAL",IF(OR(AND($E12="High",$F12="Medium"),AND($E12="Medium",$F12="High")),"HIGH",IF(AND($E12="Low",$F12="Low"),"LOW","MEDIUM")))) -> HIGH | L12: Planning Risk — To Be Validated
A13: R06 | B13: Long procurement lead times govern the critical path | C13: Fire suppression equipment can carry extended manufacturing lead times. | D13: Installation start is deferred; overall completion date slips. | E13: Medium | F13: High | G13: Obtain lead-time confirmation at quotation stage; pre-order long-lead items after approval. | H13: Main Contractor (TBC) | I13: TBD | J13: Open | K13: =IF(OR($E13="",$F13="",$E13="TBC",$F13="TBC"),"TBC",IF(AND($E13="High",$F13="High"),"CRITICAL",IF(OR(AND($E13="High",$F13="Medium"),AND($E13="Medium",$F13="High")),"HIGH",IF(AND($E13="Low",$F13="Low"),"LOW","MEDIUM")))) -> HIGH | L13: Planning Risk — To Be Validated
A14: R07 | B14: Approval turnaround for submittals is undefined | C14: No approval authority or review duration has been agreed. | D14: Engineering gate slips and delays procurement release. | E14: Medium | F14: Medium | G14: Agree the approval matrix and a maximum review turnaround at kickoff. | H14: Client Representative (TBC) | I14: TBD | J14: Open | K14: =IF(OR($E14="",$F14="",$E14="TBC",$F14="TBC"),"TBC",IF(AND($E14="High",$F14="High"),"CRITICAL",IF(OR(AND($E14="High",$F14="Medium"),AND($E14="Medium",$F14="High")),"HIGH",IF(AND($E14="Low",$F14="Low"),"LOW","MEDIUM")))) -> MEDIUM | L14: Planning Risk — To Be Validated
A15: R08 | B15: Trade congestion inside the trailers | C15: Civil, electrical, rack and fire system trades share a confined trailer envelope. | D15: Work front conflicts, rework and reduced productivity. | E15: Medium | F15: Medium | G15: Produce a sequenced work-front plan and a shared trailer access schedule. | H15: Site Supervisor (TBC) | I15: TBD | J15: Open | K15: =IF(OR($E15="",$F15="",$E15="TBC",$F15="TBC"),"TBC",IF(AND($E15="High",$F15="High"),"CRITICAL",IF(OR(AND($E15="High",$F15="Medium"),AND($E15="Medium",$F15="High")),"HIGH",IF(AND($E15="Low",$F15="Low"),"LOW","MEDIUM")))) -> MEDIUM | L15: Planning Risk — To Be Validated
A16: R09 | B16: Power availability of remaining trailers unverified | C16: The survey addresses the Trailer-2 power constraint only. | D16: A further power constraint may emerge late and block additional work fronts. | E16: Medium | F16: Medium | G16: Verify and record the power status of every trailer before releasing installation. | H16: Electrical Contractor (TBC) | I16: TBD | J16: Open | K16: =IF(OR($E16="",$F16="",$E16="TBC",$F16="TBC"),"TBC",IF(AND($E16="High",$F16="High"),"CRITICAL",IF(OR(AND($E16="High",$F16="Medium"),AND($E16="Medium",$F16="High")),"HIGH",IF(AND($E16="Low",$F16="Low"),"LOW","MEDIUM")))) -> MEDIUM | L16: Planning Risk — To Be Validated
A17: R10 | B17: Interface between fire systems and DC racks not yet defined | C17: Rack layout and installation areas are not yet fixed. | D17: Detection coverage and suppression arrangement may require redesign after rack installation. | E17: Medium | F17: Medium | G17: Freeze the rack layout before finalising detection and suppression shop drawings. | H17: Fire & Life Safety Engineer (TBC) | I17: TBD | J17: Open | K17: =IF(OR($E17="",$F17="",$E17="TBC",$F17="TBC"),"TBC",IF(AND($E17="High",$F17="High"),"CRITICAL",IF(OR(AND($E17="High",$F17="Medium"),AND($E17="Medium",$F17="High")),"HIGH",IF(AND($E17="Low",$F17="Low"),"LOW","MEDIUM")))) -> MEDIUM | L17: Planning Risk — To Be Validated
A19: Risk Rating is derived from Probability × Severity: High/High = CRITICAL; High/Medium = HIGH; Low/Low = LOW; all other combinations = MEDIUM.

Sheet 7. Document Control
A1: FIRE FIGHTING SYSTEM — NEW DC
A2: Installation Schedule & Project Responsibility Tracker
A3: Survey Date: 30-Jun-2026 | PM: Kharsan Mujeb Al Ajmi | [OFFICIAL LOGO — TO BE INSERTED]
A6: DOCUMENT CONTROL
A7: Document Title | B7: Fire Fighting System Installation Schedule
A8: Project | B8: New DC
A9: Asset / Location | B9: Mobile / Trailer-based DC
A10: Source Document | B10: RC Vehicle Survey Report – Fire Fighting System for New DC
A11: Survey Date | B11: 30-Jun-2026
A12: Project Manager | B12: Kharsan Mujeb Al Ajmi
A13: Version | B13: 0.1
A14: Status | B14: Preliminary — Planning Baseline
A15: Prepared By | B15: TBC
A16: Reviewed By | B16: TBC
A17: Approved By | B17: TBC
A18: Last Updated | B18: TBC
A20: REVISION HISTORY
